Workbook
Name Occupancy: Inputs!$E$31:$E$32

Sheet Inputs
C1: Project: | D1: 1856 WIDE TEX | F1: input
F2: calc'd cells
E3: UNITS
E4: A | F4: B | G4: C | H4: D | I4: E | J4: F | K4: G | L4: H | M4: G | N4: H | O4: I | P4: J | Q4: K | R4: L | S4: M
D5: Unit length | E5: 56 | O5: 0 | P5: 0 | Q5: 0 | R5: 0 | S5: 0 | T5: =SUM(E5:S5) -> 56 | U5: lf
D6: Unit width | E6: 17.75 | O6: 0 | P6: 0 | Q6: 0 | R6: 0 | S6: 0 | T6: =SUM(E6:S6) -> 17.75 | U6: lf
D7: Bldg width | E7: =T6 -> 17.75
D8: Bldg length | E8: =E5 -> 56
D9: Unit SF | E9: =E6*E5 -> 994 | F9: =F6*F5 -> 0 | G9: =G6*G5 -> 0 | H9: =H6*H5 -> 0 | I9: =I6*I5 -> 0 | J9: =J6*J5 -> 0 | K9: =K6*K5 -> 0 | L9: =L6*L5 -> 0 | ... S9: =S6*S5 -> 0 | T9: =SUM(E9:S9) -> 994 | U9: sf
D10: Number of units | E10: 1 | T10: =SUM(E10:S10) -> 1 | U10: total units
D11: Unit Dead weight | E11: =E9*28 -> 27832 | F11: =F9*28 -> 0 | G11: =G9*28 -> 0 | H11: =H9*28 -> 0 | I11: =I9*28 -> 0 | J11: =J9*28 -> 0 | K11: =K9*28 -> 0 | L11: =L9*28 -> 0 | ... S11: =S9*28 -> 0 | T11: =SUM(E11:S11) -> 27832
D12: Axles | E12: =ROUNDUP(E11/5500,0) -> 6 | F12: =ROUNDUP(F11/5500,0) -> 0 | G12: =ROUNDUP(G11/5500,0) -> 0 | H12: =ROUNDUP(H11/5500,0) -> 0 | I12: =ROUNDUP(I11/5500,0) -> 0 | J12: =ROUNDUP(J11/5500,0) -> 0 | K12: =ROUNDUP(K11/5500,0) -> 0 | L12: =ROUNDUP(L11/5500,0) -> 0 | ... S12: =ROUNDUP(S11/5500,0) -> 0 | T12: =SUM(E12:S12) -> 6 | U12: total axles
D13: Unit with Live Loads | E13: =(E9*28)+((Specs!$J$24+Specs!$J$25)*Inputs!E9) -> 107352 | F13: =(F9*28)+((Specs!$J$24+Specs!$J$25)*Inputs!F9) -> 0 | G13: =(G9*28)+((Specs!$J$24+Specs!$J$25)*Inputs!G9) -> 0 | H13: =(H9*28)+((Specs!$J$24+Specs!$J$25)*Inputs!H9) -> 0 | I13: =(I9*28)+((Specs!$J$24+Specs!$J$25)*Inputs!I9) -> 0 | J13: =(J9*28)+((Specs!$J$24+Specs!$J$25)*Inputs!J9) -> 0 | K13: =(K9*28)+((Specs!$J$24+Specs!$J$25)*Inputs!K9) -> 0 | L13: =(L9*28)+((Specs!$J$24+Specs!$J$25)*Inputs!L9) -> 0 | ... S13: =(S9*28)+((Specs!$J$24+Specs!$J$25)*Inputs!S9) -> 0 | T13: =T12*2 -> 12 | U13: total tires
F14: weight per spacing in kps
C15: Unit "A" | D15: Beam length | E15: =E5*2 -> 112 | F15: 1 | G15: 2 | H15: 3 | I15: 4 | J15: 5 | K15: 6 | L15: 7 | M15: 8 | N15: 9 | O15: 10 | P15: 11
D16: Weight per lf | E16: =E13/E15 -> 958.5 | F16: =($E$16*F15)/1000 -> 0.9585 | G16: =($E$16*G15)/1000 -> 1.917 | H16: =($E$16*H15)/1000 -> 2.8755 | I16: =($E$16*I15)/1000 -> 3.834 | J16: =($E$16*J15)/1000 -> 4.7925 | K16: =($E$16*K15)/1000 -> 5.751 | L16: =($E$16*L15)/1000 -> 6.7095 | M16: =($E$16*M15)/1000 -> 7.668 | ... P16: =($E$16*P15)/1000 -> 10.5435
H17: =(H16/2)+$G$16 -> 3.35475 | I17: =(I16/2)+$G$16 -> 3.834 | J17: =(J16/2)+$G$16 -> 4.31325 | K17: =(K16/2)+$G$16 -> 4.7925 | L17: =(L16/2)+$G$16 -> 5.27175 | M17: =(M16/2)+$G$16 -> 5.751 | N17: =(N16/2)+$G$16 -> 6.23025 | O17: =(O16/2)+$G$16 -> 6.7095 | P17: =(P16/2)+$G$16 -> 7.18875 | Q17: 1/2 plus 1st 2'
F18: weight per spacing in kps
C19: Unit "B" | D19: Beam length | E19: =F5*2 -> 0 | F19: 1 | G19: 2 | H19: 3 | I19: 4 | J19: 5 | K19: 6 | L19: 7 | M19: 8
D20: Weight per lf | E20: =F13/E19 -> #DIV/0! | F20: =($E$20*F19)/1000 -> #DIV/0! | G20: =($E$20*G19)/1000 -> #DIV/0! | H20: =($E$20*H19)/1000 -> #DIV/0! | I20: =($E$20*I19)/1000 -> #DIV/0! | J20: =($E$20*J19)/1000 -> #DIV/0! | K20: =($E$20*K19)/1000 -> #DIV/0! | L20: =($E$20*L19)/1000 -> #DIV/0! | M20: =($E$20*M19)/1000 -> #DIV/0!
H21: =(H20/2)+$G$16 -> #DIV/0! | I21: =(I20/2)+$G$16 -> #DIV/0! | J21: =(J20/2)+$G$16 -> #DIV/0! | K21: =(K20/2)+$G$16 -> #DIV/0! | L21: =(L20/2)+$G$16 -> #DIV/0! | M21: =(M20/2)+$G$16 -> #DIV/0! | N21: 1/2 plus 1st 2'
D24: Occupancy | E24: B
D27: Unit total sf | E27: =T9 -> 994 | F27: sf
D28: Building Area | E28: =E8*E7 -> 994 | F28: sf
D29: Building perimeter | E29: =(E8*2)+(E7*2) -> 147.5 | F29: lf
C31: 2003 IBC | D31: Occupancy | E31: B | F31: Load | G31: =E28/100 -> 9.94 | H31: =ROUNDDOWN(G31,0) -> 9
C32: 2003 IBC | D32: Occupancy | E32: E | F32: Load | G32: =E28/20 -> 49.7 | H32: =ROUNDDOWN(G32,0) -> 49 | J32: CFM EA. | K32: FRESH AIR
C33: 2003 IMC | D33: Ventilation Load "B" | E33: =7/1000 -> 0.007 | G33: =E33*$E$28 -> 6.958 | H33: =ROUNDUP(G33,0) -> 7 | J33: 20 | K33: =J33*H33 -> 140 | L33: CFM "B"
C34: 2003 IMC | D34: Ventilation Load "E" | E34: =50/1000 -> 0.05 | G34: =E34*$E$28 -> 49.7 | H34: =ROUNDUP(G34,0) -> 50 | J34: 15 | K34: =J34*H34 -> 750 | L34: CFM "E"
F35: waste @ 5%
D36: Skirting 4x12 sheets | E36: =E29/16 -> 9.21875 | F36: =E36*1.05 -> 9.6796875 | G36: =ROUNDUP(F36,0) -> 10 | M36: Try your quantities here to see if will work.
D37: 12" x 12" Vents | E37: =E28/150 -> 6.6266667 | F37: =ROUNDUP(E37,0) -> 7
M38: QTY 2-TUBE | N38: QTY 24"U | O38: TOTAL WATTS
C39: Office 1.3/sf | D39: Allowed Lighting 2001 ASHARE 90.1 | F39: =$E$28*1.3 -> 1292.2 | G39: watts | H39: =F39/120 -> 10.768333 | I39: amps | J39: =F39/92 -> 14.045652 | K39: 3-bulb fixtures | M39: 0 | N39: 0 | O39: =(M39*'Electrical 1-ph'!$Z$4)+(N39*'Electrical 1-ph'!$Z$7) -> 0 | P39: =IF(F39>O39,"Passes ","Fails") -> Passes
C40: Office 1.0/sf(1.1 bysection) | D40: Allowed lighting 2004 ASHARE 90.1 | F40: =$E$28*1 -> 994 | G40: watts | H40: =F40/120 -> 8.2833333 | I40: amps | J40: =F40/68 -> 14.617647 | K40: 2-bulb fixtures | M40: 18 | N40: 0 | O40: =(M40*'Electrical 1-ph'!$Z$5)+(N40*'Electrical 1-ph'!$Z$7) -> 1044 | P40: =IF(F40>O40,"Passes ","Fails") -> Fails
C41: Office 1/sf | D41: Allowed Lighting 2003 IECC | F41: =$E$28*1 -> 994 | G41: watts | H41: =F41/120 -> 8.2833333 | I41: amps | J41: =F41/92 -> 10.804348 | K41: 3-bulb fixtures | M41: 0 | N41: 0 | O41: =(M41*'Electrical 1-ph'!$Z$4)+(N41*'Electrical 1-ph'!$Z$7) -> 0 | P41: =IF(F41>O41,"Passes ","Fails") -> Passes
C42: Office 1/sf | D42: Allowed Lighting 2006 IECC | F42: =$E$28*1 -> 994 | G42: watts | H42: =F42/120 -> 8.2833333 | I42: amps | J42: =F42/92 -> 10.804348 | K42: 3-bulb fixtures | M42: 0 | N42: 0 | O42: =(M42*'Electrical 1-ph'!$Z$4)+(N42*'Electrical 1-ph'!$Z$7) -> 0 | P42: =IF(F42>O42,"Passes ","Fails") -> Passes
C43: School/University 1.5/sf | D43: Allowed Lighting 2001 ASHARE 90.1 | F43: =$E$28*1.5 -> 1491 | G43: watts | H43: =F43/120 -> 12.425 | I43: amps | J43: =F43/92 -> 16.206522 | K43: 3-bulb fixtures | M43: 0 | N43: 0 | O43: =(M43*'Electrical 1-ph'!$Z$4)+(N43*'Electrical 1-ph'!$Z$7) -> 0 | P43: =IF(F43>O43,"Passes ","Fails") -> Passes
C44: School/University 1.2/sf | D44: Allowed Lighting 2003 IECC | F44: =$E$28*1.2 -> 1192.8 | G44: watts | H44: =F44/120 -> 9.94 | I44: amps | J44: =F44/92 -> 12.965217 | K44: 3-bulb fixtures | M44: 0 | N44: 0 | O44: =(M44*'Electrical 1-ph'!$Z$4)+(N44*'Electrical 1-ph'!$Z$7) -> 0 | P44: =IF(F44>O44,"Passes ","Fails") -> Passes
C45: School/University 1.2/sf | D45: Allowed Lighting 2006 IECC | F45: =$E$28*1.2 -> 1192.8 | G45: watts | H45: =F45/120 -> 9.94 | I45: amps | J45: =F45/92 -> 12.965217 | K45: 3-bulb fixtures | M45: 0 | N45: 0 | O45: =(M45*'Electrical 1-ph'!$Z$4)+(N45*'Electrical 1-ph'!$Z$7) -> 0 | P45: =IF(F45>O45,"Passes ","Fails") -> Passes
...

Sheet Specs
F8: DESIGN CRITERIA: | N8: FLOOR: | V8: ROOF: | AC8: TELECOM:
F9: PROJECT NAME: | I9: MODULAR OFFICE COMPLEX | N9: BOTTOM BOARD: | P9: ROLL, POLYETHYLENE FIBER MESH | V9: RAFTER: | W9: 2X8 #2SYP 16" O.C.
F10: BUILDING SQUARE FOOTAGE: | K10: TBA | N10: INSULATION: | P10: R-22 FACED | R10: 35% RECYCLED CONTENT GREEN GUARD | V10: RIM: | W10: 1.9e LVL 14 1/4" TAPER T0 7 1/4"
F11: CODES: | N11: JOIST: | P11: 2X8 #2SYP OR BETTER AT 16" O.C. | V11: SHEATHING: | W11: 7/16" MULE-HIDE FR DECK PANEL C | AD11: J BOXES IN WALL STUBBED ABOVE CEILING 3/4" CONDUIT
G12: ELECTRICAL: NEC-2008 | N12: SIDEBAND JOIST (RIM): | P12: 2X8 #2SYP OR BETTER | V12: COVERING: | W12: WHITE REFLECTIVE STD .045 MULE-HIDE EPDM ADHERED W/ MULE-HIDE
G13: BUILDING: IBC-2006 | N13: DECKING: | P13: 2 X 3/4" T&G DRYGUARD | X13: ACRYLIC WATER BASED BONDING ADHESIVE
G14: PLUMBING: IPC-2006 | N14: UNDERLAYMENT: | P14: 1/4" FIBEROCK - 95% RECYCLED CONTENT | V14: BOTTOM RAFTER SHEATHING: | W14: NETTING | AC14: TRANSPORTATION:
G15: MECHANICAL: IMC-2006 | N15: COVERING: | P15: 1/8" VCT: WHITE #51899 - FLOORSCORE RECYCLED | V15: ROOF PITCH: | W15: .25/12 TRANSVERSE
G16: ENERGY: IEEC-2006 | P16: OFFICES 22OZ CARPET TILES CONTENT CRI GRN LABLE + | V16: CEILING: | W16: 8'-6" HGT IN OFFICE AREAS, 2X4 PANELS 32% RECYCLED CONTENT | AC16: 7/16 | AD16: ROOF DECK | AG16: =0.5/12 -> 0.041666667
G17: ADA: TAS 1994 | N17: BASE COVE: | P17: 4" RUBBER: COLOR= GREY - 6" IN RR RECYCLED CONTENT 10% | V17: TRUSSES: | W17: N/A
F18: USE GROUP: | I18: =Inputs!E24 -> B | V18: INSULATION: | W18: (2) LAYERS R-15 (1 LAYER FACED TOWARD WARM SIDE) 35% RECYCLED CONTENT | AC18: 1.9 LVL | AD18: LVL TAPER MATE BEAM | AG18: 1.33
F19: CONSTRUCTION TYPE: | I19: IBC: V-B | N19: EXTERIOR WALLS: | V19: PLENUM: | W19: N'A | AC19: 0 | AG19: 0
N20: SIDEWALL HEIGHT: 10'-1 1/8" | V20: VENTS: | W20: 1" ABOVE INSULATION | AC20: 10'-1 1/8" | AE20: TALLEST WALL | AG20: 10.1
F21: PERMISSIBLE GAS TYPE: | J21: LP | K21: NATURAL | L21: N/A | N21: STUDS: 2X4 #2SYP 16"O.C. | AC21: 1/4" | AE21: FLOOR COVER | AG21: =0.25/12 -> 0.020833333
N22: BOTTOM PLATE: SINGLE 2X4 #2SPF MIN. | AC22: 2x 3/4" | AE22: FLOOR DECK | AG22: 0.125
F23: DESIGN LOADS: | N23: TOP PLATES: DOUBLE 2X4 #3SPF MIN. | V23: ELECTRICAL: | AC23: 2X8 | AE23: FLOOR JOIST | AG23: =7.25/12 -> 0.60416667
F24: ROOF LIVE LOAD: | J24: 30 | K24: PSF | N24: HEADERS: | O24: DOUBLE 2X6 #2SYP(MIN.) W/ 7/16" FILLER | V24: SERVICE: | W24: 120/240V OR 120/208 SINGLE PHASE PER ONSITE REQ. | AC24: 2'-1" | AE24: TO ROAD APPROX | AG24: 2.583
F25: FLOOR LIVE LOAD: | J25: 50 | K25: PSF (SEE S-101 FOR 50 LB SPACING) | N25: JACK STUDS: SINGLE EACH SIDE 2X4 #2SYP | V25: LOAD CENTER: | W25: 125 AMP (AS SHOWN) , INT MOUNT LOAD CNT. W/ #6 BARE GROUND | AG25: =SUM(AG16:AG24) -> 14.804667 | AH25: FT
F26: CONC. FLOOR LIVE LOAD: | J26: 2000 LBS | N26: FIRE BLOCK: OPTIONAL 2X4 ON EDGE AT CEILING LINE. N/A IF ROCK GOES TO TOP PLATE. | AF26: TOTAL | AG26: 14'-10" | AH26: APPROX.
F27: WIND LOAD: | J27: (130 MPH 3-SEC GUST) | N27: INSULATION: R-15 FACED | Q27: 35% RECYCLED CONTENT | V27: ENTRANCE: | W27: 1 1/2 " NIPPLE DOWN METAL | AE27: UNIT WEIGHT APPROX. | AG27: =B5*28 -> 0 | AH27: LBS
F28: EXPOSURE: | I28: B | N28: SHEATHING: 7/16" OSB ENDWALLS | V28: WIRING: | W28: MC #12,#10 E-MAX,#6 AT HVAC ALL COPPER 20% RECYCLED CONTENT
F29: SEISMIC DESIGN CATEGORY: | J29: B | N29: SIDING: 3/8" SMART PANEL WOOD SIDING | V29: LIGHTS: | W29: 48" T-8 (2) TUBE 32 WATT FLOUR. FIXTURES (58 FIXTUREWATTS)
N30: TRIM: 1X4 SMART PANEL WOOD | W30: PHOTO CELL EXTERIOR LIGHT- FULLY SHEILDED FLUORESCENT | AC30: ENERGY CODE COMPLIANCE
F31: SPECIAL CONDITIONS AND/OR LIMITATIONS: | V31: WEATHERHEADS: | W31: N/A | AC31: 2-PLEX COMCHECK CERTIFICATES TO BE USED AS CHECKLIST.
F32: 1. HANDICAP ACCESS TO BE PROVIDED PER 1994 TAS AS REQUIRED BY OTHERS. | V32: FANS: | W32: 90 CFM EXHAUST | AC32: 2 TUBE LIGHT FIXTURE IS 68 FIXTURE WATTS
F33: 2. BUILDING TO BE LOCATED PER TABLE 602 OF THE 2006 IBC. | V33: SURGE PROTECT: | W33: N/A | AC33: 2'X2'- U TUBE FIXTURE IS 38 FIXTURE WATTS
F34: 3. ANY REQUIRED ALARM SYSTEM WILL BE OPTIONAL. | N34: INTERIOR WALLS (ALL FULL HEIGHT TO RAFTERS): | V34: EXIT/EMERG. LIGHT: | W34: EXIT/EMEG. COMBO LIGHT OR EMEG. BATTERY BACK UP AS SHOWN. | AC34: EXTERIOR LIGHT IS 13 WATT@860 LUMENS = 66 LUMEN PER WATT.
F35: 4. WATER FOUNTAIN SHALL BE FURNISHED BY OTHERS PER IPC-2006 TABLE 403.1. | N35: WALL HIEGHT: 10'-1 1/8" | V35: RECIEPTS | W35: STD. 120V DUPLEX TAMPER PROOF RECEP. | AC35: WINDOWS ARE NFRC LABELED AS: U=.51 AND SHGC=.34 OR BETTER
F36: 5. ELECT. GROUNDING TO BE DONE IN THE FIELD BY OTHERS, FRAME TO FRAME & FRAME TO GROUND. | N36: STUDS 2X4 #2SYP 16" O.C. | W36: GFCI 120V STD. DUPLEX RECEPTACLES | AC36: DESIGNED FOR CLIMATE ZONE 3A
F37: 6. HANDICAP RESTROOMS PROVIDED BY OTHERS PER IPC-2006 TABLE 403.1 | N37: BOTTOM PLATE: SINGLE 2X4 #2SPF MIN. | W37: W.P. EXT. GFCI 120V RECEPTACLE | AC37: DOOR U VALUE IS DEFAULT .7
N38: TOP PLATES: DOUBLE 2X4 #2SPF MIN.
F39: BLOCKING NOTES: | N39: FIRE BLOCKS: 2X4 ON EDGE AT CEILING LINE | V39: SWITCHES | W39: 120V SINGLE POLE SWITCH, 3WAY AND DIMMER WHERE SHOWN.
F40: 1. TIE DOWN/BLOCKING/ANCHORING: IN ACCORDANCE WITH STRUCTURAL ENGINEERS DESIGN | N40: COVERING: 5/8" FIRE-X VCG 50% RECYCLED CONTENT | S40: COLOR: HAMPTON GRAY | V40: J-BOXES: | W40: ALL PLATES TO BE IVORY (EXCEPT RR) | AC40: COMCHECK AREA
F41: 2. CRAWL SPACE VENTILATION PROVIDED BY SITE INSTALLER PER 1203.3.1 OF 2006 IBC. | O41: 5/8" GREEN BOARD AT RESTROOM COVERED WITH FRP (2) WALLS | V41: ALARM: | W41: N/A | AC41: (1)SIDEWALL = 56' X 10'-1 1/8" = 566 SF
N42: TRIM: STANDARD VCG BATTENS | V42: MISC: | W42: GROUNDING ON SITE TO BE PER NEC 2008, 250-96 | AC42: (1)ENDWALL = 17'-9" X 10'-1 1/8" = 179 SF
N43: FRP: 4' (MIN.)WAINSCOT AT RESTROOM (2) WALLS | AC43: SIDEWALL X 2= 1132 SF + ENDWALL X 6 = 358 SF FOR A TOTAL OF 1490 SF
F44: SCOPE OF WORK: | N44: INSULATION: R-15 THROUGHOUT. | V44: PLUMBING:
F45: NOT INCLUDED IN SCOPE OF WORK (OPTIONAL ITEMS) | V45: WATER SUPPLY: | W45: TYPE "L" COPPER - 20% RECYCLED CONTENT
F46: 1. | G46: UTILITIES AND UTILITY CONNECTIONS | V46: WASTE: | W46: PVC SCHEDULE 40 (MULTIPLE DROPS)
F47: 2. | G47: POURED CONCRETE (DRIVEWAY, SIDEWALK, SLABS, FOOTINGS, ECT.) | N47: WINDOWS: | V47: WATER HEATER: | W47: ON DEMAND WATER HEATER - ENERGY EFFICIENT
...

Sheet AC duct
X2: DAMPER
G3: INSIDE DIM. | K3: 10'-1 1/8" WALLS | O3: 10'-1 1/8" WALLS | X3: OPEN
A4: Item | B4: MODEL | C4: WIDTH | E4: HEIGHT | F4: DEPTH | G4: SUPPLY | H4: W/INSUL | I4: COINS OPNG | J4: OPNG HEAD | K4: CENTER AFF | L4: RETURN | M4: RETURN W/1/2" | N4: OPNG HEAD | O4: CENTER AFF | P4: WIDTH-FLANGE | Q4: EER | R4: SEER | S4: WEIGHT | T4: BREAKER | U4: WIRE | V4: CFM | W4: AMP LOADS | X4: MAX FRESH | Y4: 8" Supply Grills | Z4: FA check
A5: 1-ton | B5: WA121-A05 | C5: 30 1/8" | E5: 46" | F5: 14 5/8" | G5: 17X5 | H5: 19X7 | I5: 20X8 | J5: 9'-10 1/8" | K5: 9'-6 1/8" (1/2" T&B CLR) | L5: 10X17 | M5: 11x18 | N5: 8'-11 1/8" | O5: 8'-5 5/8" (1/2" T&B CLR) | P5: 32 | Q5: 9 | R5: 10 | S5: 155 | T5: 30 | U5: #10 | V5: 485 | X5: =V5*0.25 -> 121.25 | Z5: =IF(X5>$C$19,"FA = OK","FA = Not Enough") -> FA = Not Enough
A6: 1-1/2 ton | B6: WA182-A10 | C6: 33.3" | E6: 70.563" | F6: 17.125" | G6: 20X8 | H6: 22X10 | I6: 23X11 | J6: 9'-10 1/8" | K6: 9'-4 5/8" (1/2" T&B CLR) | L6: 12X20 | M6: 13x20 | N6: 7'-3 15/16" | O6: 6'-9 7/16"(1/2"T&B CLR) | P6: 35 | Q6: 9.2 | R6: 10.2 | S6: 300 | T6: 60 | U6: #6 | V6: 650 | W6: 42.7 | X6: =V6*0.25 -> 162.5 | Y6: =V6/200 -> 3.25 | Z6: =IF(X6>$C$19,"FA = OK","FA = Not Enough") -> FA = OK
A7: 2-ton | B7: WA242-A10 | C7: 33.3" | E7: 70.563" | F7: 17.125" | G7: 20X8 | H7: 22X10 | I7: 23X11 | J7: 9'-10 1/8" | K7: 9'-4 5/8" (1/2" T&B CLR) | L7: 12X20 | M7: 13x20 | N7: 7'-3 15/16" | O7: 6'-9 7/16"(1/2"T&B CLR) | P7: 35 | Q7: 9.2 | R7: 10.2 | S7: 300 | T7: 60 | U7: #6 | V7: 800 | W7: 42.7 | X7: =V7*0.25 -> 200 | Y7: =V7/200 -> 4 | Z7: =IF(X7>$C$19,"FA = OK","FA = Not Enough") -> FA = OK
A8: 2 1/2-ton | B8: WA302-A10 | C8: 38.2" | E8: 70.563" | F8: 17.125" | G8: 28X8 | H8: 30X10 | I8: 31x11 | J8: 9'-10 1/8" | K8: 9'-4 5/8" (1/2" T&B CLR) | L8: 14X28 | M8: 15x29 | N8: 7'-6 15/16" | O8: 6'-11 7/16"(1/2"T&B CLR) | P8: 40 | Q8: 9.3 | R8: 10.6 | S8: 355 | T8: 60 | U8: #6 | V8: 1000 | W8: 47 | X8: =V8*0.25 -> 250 | Y8: =V8/200 -> 5 | Z8: =IF(X8>$C$19,"FA = OK","FA = Not Enough") -> FA = OK
A9: 3-ton | B9: WA372-A10 | C9: 38.2" | E9: 70.563" | F9: 17.125" | G9: 28X8 | H9: 31X11 | I9: 33X13 | J9: 9'-10 1/8" | K9: 9'-4 5/8" (1/2" T&B CLR) | L9: 14X28 | M9: 15x29 | N9: 7'-6 15/16" | O9: 6'-11 7/16"(1/2"T&B CLR) | P9: 40 | Q9: 9.2 | R9: 10 | S9: 355 | T9: 60 | U9: #6 | V9: 1100 | W9: 47 | X9: =V9*0.25 -> 275 | Y9: =V9/200 -> 5.5 | Z9: =IF(X9>$C$19,"FA = OK","FA = Not Enough") -> FA = OK
A10: 3-1/2 ton | B10: WA423-A10 | C10: 42.075" | E10: 84.875" | F10: 22.432" | G10: 30X10 | H10: 32X12 | I10: 33X13 | J10: 9'-10 1/8" | K10: 9'-3 5/8" (1/2" T&B CLR) | L10: 16X30 | M10: 17x31 | N10: 6'-4 7/16" | O10: 5'-7 15/16"(1/2" t&b CLR) | P10: 43.88 | Q10: 9.2 | R10: 10.6 | S10: 500 | T10: 60 | U10: #6 | V10: 1400 | W10: 47 | X10: =V10*0.25 -> 350 | Y10: =V10/200 -> 7 | Z10: =IF(X10>$C$19,"FA = OK","FA = Not Enough") -> FA = OK
A11: 4-ton | B11: WA484-A10 | C11: 42.075" | E11: 84.875" | F11: 22.432" | G11: 30X10 | H11: 32X12 | I11: 33X13 | J11: 9'-10 1/8" | K11: 9'-3 5/8" (1/2" T&B CLR) | L11: 16X30 | M11: 17x31 | N11: 6'-4 7/16" | O11: 5'-7 15/16"(1/2" t&b CLR) | P11: 43.88 | Q11: 9.6 | R11: 11 | S11: 500 | T11: 60 | U11: #6 | V11: 1550 | W11: 47 | X11: =V11*0.25 -> 387.5 | Y11: =V11/200 -> 7.75 | Z11: =IF(X11>$C$19,"FA = OK","FA = Not Enough") -> FA = OK
A12: 5-ton | B12: WA602-A10 | C12: 42.075" | E12: 84.875" | F12: 22.432" | G12: 30X10 | H12: 32X12 | I12: 33X13 | J12: 9'-10 1/8" | K12: 9'-3 5/8" (1/2" T&B CLR) | L12: 16X30 | M12: 17x31 | N12: 6'-4 7/16" | O12: 5'-7 15/16"(1/2" t&b CLR) | P12: 43.88 | Q12: 8.7 | R12: 10.2 | S12: 500 | T12: 60 | U12: #6 | V12: 1700 | W12: 47 | X12: =V12*0.25 -> 425 | Y12: =V12/200 -> 8.5 | Z12: =IF(X12>$C$19,"FA = OK","FA = Not Enough") -> FA = OK
B17: OCCUPANTS | C17: =IF(Inputs!E24=Inputs!E31,Inputs!H33,Inputs!H34) -> 7
B18: CFM REQ'D EACH | C18: =IF(Inputs!E24=Inputs!E31,Inputs!J33,Inputs!J34) -> 20 | D18: CFM
B19: TOTAL OUTSIDE REQD | C19: =C18*C17 -> 140 | D19: CFM | L19: SUPPLY | M19: 1-1/2" R-6 DUCT BOARD
L20: RETURN | M20: 1-1/2" R-6 DUCT BOARD
L21: EXH | M21: 90 CFM EXHAUST FAN
L22: SA1 | M22: 24"X24" GRILL W/6" FLEX
L23: SA2 | M23: 24"X24" GRILL W/8" FLEX
L24: RA1 | M24: 24"X24" GRILL W/6" FLEX
L25: RA2 | M25: 24"X24" GRILL W/8" FLEX
L26: RA3 | M26: 24"X24" GRILL W/12" FLEX
L27: T | M27: PROGRAMABLE THERMOSTAT
L28: HVAC | M28: 3-TON BARD(WA372-A10) W/10KW
E42: 8-PLEX HEAT AND AIR
G44: NOR | H44: NOO | I44: NOO | J44: NOO | K44: NOC | L44: NOO | M44: NOO | N44: NOR | O44: TOTAL | P44: HVAC CALC
E45: BTUH | F45: HEAT | G45: 25598 | H45: 20478 | I45: 20478 | J45: 20478 | K45: 12799 | L45: 20478 | M45: 20478 | N45: 25598 | O45: =SUM(G45:N45) -> 166385 | P45: 162171 | Q45: =O45-P45 -> 4214
E46: TONNAGE | F46: AIR | G46: 3 | H46: 3 | I46: 3 | J46: 3 | K46: 3 | L46: 3 | M46: 3 | N46: 3 | O46: =SUM(G46:N46) -> 24 | P46: 24.5 | Q46: =O46-P46 -> -0.5 | T46: 2-BULB | V46: LIGHTS | X46: 10 | Y46: 12 | Z46: 12 | AA46: 12 | AB46: 8 | AC46: 12 | AD46: 12 | AE46: 12 | AF46: =SUM(X46:AE46) -> 90
T47: 24U | V47: LIFGT | X47: 3 | AB47: 2 | AF47: =SUM(X47:AE47) -> 5
E49: 7-PLEX HEAT AND AIR
G51: NOR | H51: NOO | J51: NOO | K51: NOC | L51: NOO | M51: NOO | N51: NOR | O51: TOTAL | P51: HVAC CALC
E52: BTUH | F52: HEAT | G52: 25598 | H52: 20478 | J52: 20478 | K52: 12799 | L52: 20478 | M52: 20478 | N52: 25598 | O52: =SUM(G52:N52) -> 145907 | P52: 146141 | Q52: =O52-P52 -> -234
E53: TONNAGE | F53: AIR | G53: 3 | H53: 3 | J53: 3 | K53: 3 | L53: 3 | M53: 3 | N53: 3 | O53: =SUM(G53:N53) -> 21 | P53: 21 | Q53: =O53-P53 -> 0
T55: 2-BULB | V55: LIGHTS | X55: 10 | Y55: 12 | Z55: 12 | AA55: 12 | AB55: 8 | AC55: 12 | AD55: 12 | AE55: 12 | AF55: =SUM(X55:AE55) -> 90
T56: 24U | V56: LIFGT | X56: 3 | AB56: 2 | AF56: =SUM(X56:AE56) -> 5
E58: 6-PLEX HEAT AND AIR
G60: NOR | H60: NOO | I60: NOO | K60: NOC | L60: NOO | M60: NOO | N60: NOR | O60: TOTAL | P60: HVAC CALC
E61: BTUH | F61: HEAT | G61: 25598 | H61: 20478 | I61: 20478 | K61: 12799 | L61: 20478 | N61: 25598 | O61: =SUM(G61:N61) -> 125429 | P61: 139095 | Q61: =O61-P61 -> -13666
E62: TONNAGE | F62: AIR | G62: 3 | H62: 3 | I62: 3 | K62: 3 | L62: 3 | N62: 3 | O62: =SUM(G62:N62) -> 18 | P62: 18 | Q62: =O62-P62 -> 0
E64: 5-PLEX HEAT AND AIR | T64: 2-BULB | V64: LIGHTS | X64: 10 | Y64: 12 | Z64: 12 | AB64: 8 | AC64: 12 | AE64: 12 | AF64: =SUM(X64:AE64) -> 66
T65: 24U | V65: LIFGT | X65: 3 | AB65: 2 | AF65: =SUM(X65:AE65) -> 5
...

Sheet Telecom

Sheet Electrical 1-ph
X2: AMPS EA. | Y2: ITEM | Z2: WATTS EA.
F3: INPUT THE "AMPS ONLY) WATTS ARE CALCULATED. | X3: 1.5 | Y3: RECEPTS | Z3: =X3*D13 -> 180
V4: BULBS | W4: 32 WATT | X4: =Z4/D13 -> 0.76666667 | Y4: LIGHTS 2'X4' 3-TUBE T-8 | Z4: 92
X5: =Z5/D13 -> 0.48333333 | Y5: LIGHTS 2'X4' 2-TUBE T-8 | Z5: 58
X6: 0.8 | Y6: 90 CFM EXHAUST FAN | Z6: =X6*D13 -> 96
V7: BULBS | W7: 32 WATT | X7: 0.31 | Y7: LIGHT 2'X2' U-TUBE T-8 | Z7: 38
B8: (SP1) 100A PANEL | X8: =Z8/120 -> 0.033333333 | Y8: EMERGENCY/EXIT | Z8: 4
X9: =Z9/120 -> 0.10833333 | Y9: PORCH LIIGHT | Z9: 13
X10: 22.9 | Y10: EeMAX | Z10: =X10*D13 -> 2748
X11: 47 | Y11: HVAC | Z11: =X11*D13 -> 5640
D12: VOLTS | F12: PHASE | I12: BREAKER | J12: TOTAL VOLTS = V x #LEGS | M12: #6 BARE GROUND | Z12: =X12*120 -> 0
D13: 120 | E13: 240 | F13: 1 | I13: 100 | J13: 240 | Z13: =X13*120 -> 0
B14: WIRE | C14: DESCRIPTION | D14: BREAKER | E14: POLE | F14: CONNECTION LOAD | J14: CIRCUIT NO. | M14: CONNECTION LOAD | Q14: POLE | R14: BREAKER | S14: DESCRIPTION | T14: WIRE | Z14: =X14*120 -> 0
F15: A(AMPS) | G15: A(WATTS) | H15: B(AMPS) | I15: B(WATTS) | M15: A(AMPS) | N15: A(WATTS) | O15: B(AMPS) | P15: B(WATTS)
B16: 6 | C16: HVAC | D16: 60 | E16: 2 | F16: 47 | G16: =F16*D13 -> 5640 | J16: 1 | K16: A | L16: 2 | M16: 1.5 | N16: =M16*D13 -> 180 | Q16: 1 | R16: 20 | S16: GFI-1 | T16: 12
B17: 6 | C17: HVAC | D17: 60 | H17: 47 | I17: =H17*D13 -> 5640 | J17: 3 | K17: B | L17: 4 | O17: =SUM(7*X3) -> 10.5 | P17: =O17*D13 -> 1260 | Q17: 1 | R17: 20 | S17: OUTLETS | T17: 12
B18: 12 | C18: OUTLETS | D18: 20 | F18: =SUM(7*X3) -> 10.5 | G18: =F18*D13 -> 1260 | J18: 5 | K18: A | L18: 6 | M18: =SUM(10*X5+X9+X8) -> 4.975 | N18: =M18*D13 -> 597 | Q18: 1 | R18: 20 | S18: LIGHTS | T18: 12
B19: 12 | C19: LIGHTS | D19: 20 | H19: =SUM(10*X5+X8+X9) -> 4.975 | I19: =H19*D13 -> 597 | J19: 7 | K19: B | L19: 8 | P19: =O19*D13 -> 0
F20: 0 | G20: =F20*D13 -> 0 | J20: 9 | K20: A | L20: 10 | N20: =M20*D13 -> 0
F21: =SUM(F16:F20) -> 57.5 | G21: =SUM(G16:G20) -> 6900 | H21: =SUM(H16:H20) -> 51.975 | I21: =SUM(I16:I20) -> 6237 | M21: =SUM(M16:M20) -> 6.475 | N21: =SUM(N16:N20) -> 777 | O21: =SUM(O16:O20) -> 10.5 | P21: =SUM(P16:P20) -> 1260
J23: TOTAL A | K23: =G21+N21 -> 7677 | L23: WATTS | M23: =K23/K25 -> 0.5059312
J24: TOTAL B | K24: =I21+P21 -> 7497 | L24: WATTS | M24: =K24/K25 -> 0.4940688
K25: =SUM(K23:K24) -> 15174 | L25: WATTS
K26: =K25/J13 -> 63.225 | L26: AMPS
K27: =K26/0.8 -> 79.03125 | L27: 0.2
J28: SIZE | K28: =I13 -> 100 | L28: AMPS
B31: (SP2 & 3) 100A PANEL
D35: VOLTS | F35: PHASE | I35: BREAKER | J35: TOTAL VOLTS = V x #LEGS | M35: #6 BARE GROUND
D36: 120 | E36: 240 | F36: 1 | I36: 100 | J36: 240
B37: WIRE | C37: DESCRIPTION | D37: BREAKER | E37: POLE | F37: CONNECTION LOAD | J37: CIRCUIT NO. | M37: CONNECTION LOAD | Q37: POLE | R37: BREAKER | S37: DESCRIPTION | T37: WIRE
F38: A(AMPS) | G38: A(WATTS) | H38: B(AMPS) | I38: B(WATTS) | M38: A(AMPS) | N38: A(WATTS) | O38: B(AMPS) | P38: B(WATTS)
B39: 6 | C39: HVAC | D39: 60 | E39: 2 | F39: 47 | G39: =F39*D36 -> 5640 | J39: 1 | K39: A | L39: 2 | M39: 1.5 | N39: =M39*D36 -> 180 | Q39: 1 | R39: 20 | S39: GFI-1 | T39: 12
B40: 6 | C40: HVAC | D40: 60 | H40: 47 | I40: =H40*D36 -> 5640 | J40: 3 | K40: B | L40: 4 | O40: =SUM(8*X3) -> 12 | P40: =O40*D36 -> 1440 | Q40: 1 | R40: 20 | S40: OUTLETS | T40: 12
B41: 12 | C41: OUTLETS | D41: 20 | F41: =SUM(8*X3) -> 12 | G41: =F41*D36 -> 1440 | J41: 5 | K41: A | L41: 6 | M41: =SUM(10*X28+X32+X31) -> 0 | N41: =M41*D36 -> 0
H42: =SUM(10*X28+X31+X32) -> 0 | I42: =H42*D36 -> 0 | J42: 7 | K42: B | L42: 8 | P42: =O42*D36 -> 0
F43: 0 | G43: =F43*D36 -> 0 | J43: 9 | K43: A | L43: 10 | N43: =M43*D36 -> 0
F44: =SUM(F39:F43) -> 59 | G44: =SUM(G39:G43) -> 7080 | H44: =SUM(H39:H43) -> 47 | I44: =SUM(I39:I43) -> 5640 | M44: =SUM(M39:M43) -> 1.5 | N44: =SUM(N39:N43) -> 180 | O44: =SUM(O39:O43) -> 12 | P44: =SUM(P39:P43) -> 1440
J46: TOTAL A | K46: =G44+N44 -> 7260 | L46: WATTS | M46: =K46/K48 -> 0.50627615
J47: TOTAL B | K47: =I44+P44 -> 7080 | L47: WATTS | M47: =K47/K48 -> 0.49372385
K48: =SUM(K46:K47) -> 14340 | L48: WATTS
...

Sheet Electrical 3-ph
B7: PANEL "SP-1" | AB7: AMPS EA. | AC7: ITEM | AD7: WATTS EA.
AB8: 1.5 | AC8: RECEPTS | AD8: =AB8*M8 -> 0
Z9: BULBS | AA9: 32 WATT | AB9: 0.77 | AC9: LIGHTS 2'X4' 3-TUBE T-8 | AD9: 92
AB10: 0.8 | AC10: 90 CFM EXHAUST FAN | AD10: =AB10*M8 -> 0
D11: VOLTS | F11: PHASE | I11: BREAKER | L11: TOTAL VOLTS = V x #LEGS | O11: #6 BARE GROUND | Z11: BULBS | AA11: 32 WATT | AB11: 0.31 | AC11: LIGHT 2'X2' U-TUBE T-8 | AD11: 38
D12: 120 | E12: 208 | F12: 3 | I12: 200AMP | L12: =3*D12 -> 360 | AB12: =AD12/120 -> 0.033333333 | AC12: EMERGENCY/EXIT | AD12: 4
B13: WIRE | C13: DESCRIPTION | D13: BREAKER | E13: POLE | F13: CONNECTION LOAD | L13: CIRCUIT NO. | O13: CONNECTION LOAD | U13: POLE | V13: BREAKER | W13: DESCRIPTION | X13: WIRE | AB13: =AD13/120 -> 0.10833333 | AC13: PORCH LIIGHT | AD13: 13
F14: A(AMPS) | G14: A(WATTS) | H14: B(AMPS) | I14: B(WATTS) | J14: C(AMPS) | K14: C(WATTS) | O14: A(AMPS) | P14: A(WATTS) | Q14: B(AMPS) | R14: B(WATTS) | S14: C(AMPS) | T14: C(WATTS) | AB14: 22.9 | AC14: EeMAX | AD14: =AB14*115 -> 2633.5
B15: 6 | C15: HVAC | D15: 60 | E15: 2 | F15: 45 | G15: =F15*D12 -> 5400 | L15: 1 | M15: A | N15: 2 | O15: 0 | P15: =O15*D12 -> 0 | U15: 2 | V15: 60 | W15: HVAC | X15: 6 | AB15: 59 | AC15: HVAC | AD15: =AB15*M8 -> 0
B16: 6 | C16: HVAC | D16: 60 | H16: 45 | I16: =H16*D12 -> 5400 | L16: 3 | M16: B | N16: 4 | Q16: 0 | R16: =Q16*D12 -> 0 | W16: HVAC | X16: 6 | AD16: =AB16*120 -> 0
B17: 10 | C17: HOT WATER HEATER | D17: 30 | E17: 2 | J17: 22.9 | K17: =J17*D12 -> 2748 | L17: 5 | M17: C | N17: 6 | S17: 12 | T17: =S17*D12 -> 1440 | U17: 1 | V17: 20 | W17: LIGHTS | X17: 12 | AD17: =AB17*120 -> 0
B18: 10 | C18: HOT WATER HEATER | D18: 30 | F18: 22.9 | G18: =F18*D12 -> 2748 | L18: 7 | M18: A | N18: 8 | P18: =O18*D12 -> 0 | AD18: =AB18*120 -> 0
C19: N/A | I19: =H19*D12 -> 0 | L19: 9 | M19: B | N19: 10 | R19: =Q19*D12 -> 0
B20: 12 | C20: OUTLETS | D20: 20 | E20: 1 | J20: =7*1.5 -> 10.5 | K20: =J20*D12 -> 1260 | L20: 11 | M20: C | N20: 12 | S20: 1.5 | T20: =S20*D12 -> 180 | W20: DEDICATED OUTLET | Z20: EO | AA20: ELECTRICAL DUPLEX OUTLET
B21: 12 | C21: DEDICATED OUTLET | D21: 20 | E21: 1 | F21: 1.5 | G21: =F21*D12 -> 180 | L21: 13 | M21: A | N21: 14 | O21: =11*1.5 -> 16.5 | P21: =O21*D12 -> 1980 | U21: 1 | V21: 20 | W21: OUTLETS | Z21: SBO | AA21: SURGE BLOC DUPLEX OUTLET
I22: =H22*D12 -> 0 | L22: 15 | M22: B | N22: 16 | R22: =Q22*D12 -> 0 | Z22: SS | AA22: MAIN SURGE SUPPRESSION
K23: =J23*D12 -> 0 | L23: 17 | M23: C | N23: 18 | T23: =S23*D12 -> 0 | Z23: DO | AA23: DEDICATED OUTLET QUAD
G24: =F24*D12 -> 0 | L24: =L23+2 -> 19 | M24: A | N24: =N23+2 -> 20 | P24: =O24*D12 -> 0 | Z24: HVAC | AA24: HEATING AND AIR UNIT
I25: =H25*D12 -> 0 | L25: =L24+2 -> 21 | M25: B | N25: =N24+2 -> 22 | R25: =Q25*D12 -> 0 | Z25: LF | AA25: LIGHT FIXTURE
K26: =J26*D12 -> 0 | L26: =L25+2 -> 23 | M26: C | N26: =N25+2 -> 24 | T26: =S26*D12 -> 0 | Z26: GFI | AA26: GROUND FAULT INTERRUPT OUTLET
G27: =F27*D12 -> 0 | L27: =L26+2 -> 25 | M27: A | N27: =N26+2 -> 26 | P27: =O27*D12 -> 0 | Z27: EF | AA27: EXHAUST FAN
I28: =H28*D12 -> 0 | L28: =L27+2 -> 27 | M28: B | N28: =N27+2 -> 28 | R28: =Q28*D12 -> 0 | Z28: WP | AA28: WEATHER PROOF
K29: =J29*D12 -> 0 | L29: =L28+2 -> 29 | M29: C | N29: =N28+2 -> 30 | T29: =S29*D12 -> 0 | Z29: PL | AA29: PORCH LIGHT
G30: =F30*D12 -> 0 | L30: =L29+2 -> 31 | M30: A | N30: =N29+2 -> 32 | P30: =O30*D12 -> 0 | Z30: SP | AA30: SERVICE PANEL
I31: =H31*D12 -> 0 | L31: =L30+2 -> 33 | M31: B | N31: =N30+2 -> 34 | R31: =Q31*D12 -> 0 | Z31: $ | AA31: OCCUPANCY SENSOR SWITCH
K32: =J32*D12 -> 0 | L32: =L31+2 -> 35 | M32: C | N32: =N31+2 -> 36 | T32: =S32*D12 -> 0 | Z32: EeMAX | AA32: INSTANT WATER HEATER
G33: =F33*D12 -> 0 | L33: =L32+2 -> 37 | M33: A | N33: =N32+2 -> 38 | P33: =O33*D12 -> 0 | Z33: EX/EML | AA33: EXIT/EMERGENCY LIGHT
I34: =H34*D12 -> 0 | L34: =L33+2 -> 39 | M34: B | N34: =N33+2 -> 40 | R34: =Q34*D12 -> 0
K35: =J35*D12 -> 0 | L35: =L34+2 -> 41 | M35: C | N35: =N34+2 -> 42 | T35: =S35*D12 -> 0
F37: =SUM(F15:F36) -> 69.4 | G37: =SUM(G15:G36) -> 8328 | H37: =SUM(H15:H36) -> 45 | I37: =SUM(I15:I36) -> 5400 | J37: =SUM(J15:J36) -> 33.4 | K37: =SUM(K15:K36) -> 4008 | O37: =SUM(O15:O36) -> 16.5 | P37: =SUM(P15:P36) -> 1980 | Q37: =SUM(Q15:Q36) -> 0 | R37: =SUM(R15:R36) -> 0 | S37: =SUM(S15:S36) -> 13.5 | T37: =SUM(T15:T36) -> 1620
K39: TOTAL A | L39: =G37+P37 -> 10308 | M39: WATTS | N39: =L39/L42 -> 0.48312711
K40: TOTAL B | L40: =I37+R37 -> 5400 | M40: WATTS | N40: =L40/L42 -> 0.25309336
K41: TOTAL C | L41: =K37+T37 -> 5628 | M41: WATTS | N41: =L41/L42 -> 0.26377953
L42: =SUM(L39:L41) -> 21336 | M42: WATTS
L43: =L42/L12 -> 59.266667 | M43: AMPS
L44: =L43/0.8 -> 74.083333 | M44: 0.2
K45: SIZE | L45: 175 | M45: AMPS
B48: PANEL "SP-2"
D52: VOLTS | F52: PHASE | I52: BREAKER | L52: TOTAL VOLTS = V x #LEGS | O52: #6 BARE GROUND
D53: 120 | E53: 208 | F53: 3 | I53: 200AMP | L53: =3*D53 -> 360
...

Sheet Plumbing
V4: WC Office | X4: Lav Office | Y4: WC Educ. | Z4: Lav Educ. | AA4: Fountain | AB4: Service Sink
V5: Occupants | W5: Qty Reqd | X5: Qty Reqd | Y5: Qty Reqd | Z5: Qty Reqd | AA5: Qty Reqd | AB5: Qty Reqd
V6: 1 | W6: 1 | X6: 1 | Y6: 1 | Z6: 1 | AA6: 1 | AB6: 1
B7: FIXTURE UNITS | G7: WATER PIPING SIZE | O7: DRAINAGE SIZING | V7: =V6+1 -> 2 | W7: 1 | X7: 1 | Y7: 1 | Z7: 1 | AA7: 1 | AB7: 1
B8: WATER | C8: DRAIN | V8: =V7+1 -> 3 | W8: 1 | X8: 1 | Y8: 1 | Z8: 1 | AA8: 1 | AB8: 1
A9: DRINKING FOUNTAIN | B9: 0.25 | C9: 0.5 | V9: =V8+1 -> 4 | W9: 1 | X9: 1 | Y9: 1 | Z9: 1 | AA9: 1 | AB9: 1
A10: LAVITORY | B10: 2 | C10: 1 | H10: FIXTURE UNITS | P10: FIXTURE UNITS | V10: =V9+1 -> 5 | W10: 1 | X10: 1 | Y10: 1 | Z10: 1 | AA10: 1 | AB10: 1
A11: SINK | B11: 2 | C11: 2 | F11: FIXTURE | G11: FIXTURE UNIT | H11: LINE 1 | I11: LINE 2 | J11: LINE 3 | K11: LINE 4 | L11: LINE 5 | N11: FIXTURE | O11: FIXTURE UNIT | P11: LINE 1 | Q11: LINE 2 | R11: LINE 3 | S11: LINE 4 | T11: LINE 5 | V11: =V10+1 -> 6 | W11: 1 | X11: 1 | Y11: 1 | Z11: 1 | AA11: 1 | AB11: 1
A12: SERVICE SINK | B12: 3 | C12: 2 | F12: URINAL | G12: 5 | H12: 5 | N12: URINAL | O12: 4 | P12: 4 | V12: =V11+1 -> 7 | W12: 1 | X12: 1 | Y12: 1 | Z12: 1 | AA12: 1 | AB12: 1
A13: WATER CLOSET | B13: 5 | C13: 4 | F13: URINAL | G13: 5 | H13: 5 | N13: URINAL | O13: 4 | P13: 4 | V13: =V12+1 -> 8 | W13: 1 | X13: 1 | Y13: 1 | Z13: 1 | AA13: 1 | AB13: 1
A14: URINAL | B14: 5 | C14: 4 | F14: FOUNTAIN | G14: 0.25 | H14: 0.25 | N14: FOUNTAIN | O14: 0.5 | P14: 0.5 | V14: =V13+1 -> 9 | W14: 1 | X14: 1 | Y14: 1 | Z14: 1 | AA14: 1 | AB14: 1
F15: WATER CLOSET | G15: 5 | H15: 5 | N15: WATER CLOSET | O15: 4 | P15: 4 | V15: =V14+1 -> 10 | W15: 1 | X15: 1 | Y15: 1 | Z15: 1 | AA15: 1 | AB15: 1
F16: WATER CLOSET | G16: 5 | H16: 5 | N16: WATER CLOSET | O16: 4 | P16: 4 | V16: =V15+1 -> 11 | W16: 1 | X16: 1 | Y16: 1 | Z16: 1 | AA16: 1 | AB16: 1
F17: LAVITORY | G17: 2 | I17: 2 | N17: LAVITORY | O17: 1 | Q17: 1 | V17: =V16+1 -> 12 | W17: 1 | X17: 1 | Y17: 1 | Z17: 1 | AA17: 1 | AB17: 1
F18: LAVITORY | G18: 2 | I18: 2 | N18: LAVITORY | O18: 1 | Q18: 1 | V18: =V17+1 -> 13 | W18: 1 | X18: 1 | Y18: 1 | Z18: 1 | AA18: 1 | AB18: 1
F19: LAVITORY | G19: 2 | I19: 2 | N19: LAVITORY | O19: 1 | Q19: 1 | V19: =V18+1 -> 14 | W19: 1 | X19: 1 | Y19: 1 | Z19: 1 | AA19: 1 | AB19: 1
F20: LAVITORY | G20: 2 | I20: 2 | N20: LAVITORY | O20: 1 | Q20: 1 | V20: =V19+1 -> 15 | W20: 1 | X20: 1 | Y20: 1 | Z20: 1 | AA20: 1 | AB20: 1
F21: WATER CLOSET | G21: 5 | J21: 5 | N21: WATER CLOSET | O21: 4 | R21: 5 | V21: =V20+1 -> 16 | W21: 1 | X21: 1 | Y21: 1 | Z21: 1 | AA21: 1 | AB21: 1
F22: WATER CLOSET | G22: 5 | J22: 5 | N22: WATER CLOSET | O22: 4 | R22: 5 | V22: =V21+1 -> 17 | W22: 1 | X22: 1 | Y22: 1 | Z22: 1 | AA22: 1 | AB22: 1
F23: SINK | G23: 2 | K23: 2 | N23: SINK | O23: 2 | S23: 2 | V23: =V22+1 -> 18 | W23: 1 | X23: 1 | Y23: 1 | Z23: 1 | AA23: 1 | AB23: 1
F24: SERVICE SINK | G24: 3 | L24: 3 | N24: SERVICE SINK | O24: 2 | T24: 3 | V24: =V23+1 -> 19 | W24: 1 | X24: 1 | Y24: 1 | Z24: 1 | AA24: 1 | AB24: 1
F25: TOTAL UNITS | G25: =SUM(G12:G24) -> 43.25 | H25: =SUM(H12:H24) -> 20.25 | I25: =SUM(I12:I24) -> 8 | J25: =SUM(J12:J24) -> 10 | K25: =SUM(K12:K24) -> 2 | L25: =SUM(L12:L24) -> 3 | N25: TOTAL UNITS | O25: =SUM(O12:O24) -> 32.5 | P25: =SUM(P12:P24) -> 16.5 | Q25: =SUM(Q12:Q24) -> 4 | R25: =SUM(R12:R24) -> 10 | S25: =SUM(S12:S24) -> 2 | T25: =SUM(T12:T24) -> 3 | V25: =V24+1 -> 20 | W25: 1 | X25: 1 | Y25: 1 | Z25: 1 | AA25: 1 | AB25: 1
V26: =V25+1 -> 21 | W26: 1 | X26: 1 | Y26: 1 | Z26: 1 | AA26: 1 | AB26: 1
N27: 3" | O27: =IF(O25<36,"3 inch ok ","Try 4") -> 3 inch ok | V27: =V26+1 -> 22 | W27: 1 | X27: 1 | Y27: 1 | Z27: 1 | AA27: 1 | AB27: 1
N28: 4" | O28: =IF(O25<36,"4 inch not needed","4 inch will work") -> 4 inch not needed | V28: =V27+1 -> 23 | W28: 1 | X28: 1 | Y28: 1 | Z28: 1 | AA28: 1 | AB28: 1
V29: =V28+1 -> 24 | W29: 1 | X29: 1 | Y29: 1 | Z29: 1 | AA29: 1 | AB29: 1
V30: =V29+1 -> 25 | W30: 1 | X30: 1 | Y30: 1 | Z30: 1 | AA30: 1 | AB30: 1
V31: =V30+1 -> 26 | W31: 2 | X31: 1 | Y31: 1 | Z31: 1 | AA31: 1 | AB31: 1
V32: =V31+1 -> 27 | W32: 2 | X32: 1 | Y32: 1 | Z32: 1 | AA32: 1 | AB32: 1
V33: =V32+1 -> 28 | W33: 2 | X33: 1 | Y33: 1 | Z33: 1 | AA33: 1 | AB33: 1
V34: =V33+1 -> 29 | W34: 2 | X34: 1 | Y34: 1 | Z34: 1 | AA34: 1 | AB34: 1
V35: =V34+1 -> 30 | W35: 2 | X35: 1 | Y35: 1 | Z35: 1 | AA35: 1 | AB35: 1
V36: =V35+1 -> 31 | W36: 2 | X36: 1 | Y36: 1 | Z36: 1 | AA36: 1 | AB36: 1
V37: =V36+1 -> 32 | W37: 2 | X37: 1 | Y37: 1 | Z37: 1 | AA37: 1 | AB37: 1
V38: =V37+1 -> 33 | W38: 2 | X38: 1 | Y38: 1 | Z38: 1 | AA38: 1 | AB38: 1
V39: =V38+1 -> 34 | W39: 2 | X39: 1 | Y39: 1 | Z39: 1 | AA39: 1 | AB39: 1
V40: =V39+1 -> 35 | W40: 2 | X40: 1 | Y40: 1 | Z40: 1 | AA40: 1 | AB40: 1
... V535: =V534+1 -> 530 | W535: 12 | X535: 8 | Y535: 11 | Z535: 11 | AA535: 6 | AB535: 1

Sheet Check
B3: Project | C3: ________________________________________________
B5: Drawings | C5: PE | D5: TDLR | E5: NO Code
B7: Designer | C7: _______________________________
B9: Frames | C9: ________________________________ | H9: Qty | J9: ea
B10: Axles: | C10: 2 | D10: 3 | E10: 4 | F10: 5 | G10: 6 | H10: Qty
B12: Floor joist/rims | C12: 2x6 | D12: 2x8 | E12: 2x10 | H12: Qty | J12: ea
B14: Decking | C14: 1/2" | D14: 5/8" | E14: 3/4" | F14: 1 1/8" | H14: Qty | I14: =Inputs!E28/32 -> 31.0625 | J14: sheets
B16: Overlay | C16: 1/4" H | H16: Qty | I16: =I14 -> 31.0625 | J16: sheets
B18: Walls | C18: 9' ballon | D18: 10' ballon | E18: 9'-1 1/8 | F18: 10'-1 1/8"
B20: Plenum wall | C20: yes | D20: no

Sheet Summation
M3: THESE PLAN ARE FOR UNITS NOA,NOR,NOO,NOC.
M4: EACH UNIT IS 825SF. THEY CAN BE CONSTRUCTED WITH THE NOA AND THE NOR BEING THE UNITS WITH EXTERIOR WALLS AND THE NOO AND NOC BEING THE CENTER UNITS.
M5: COMCHECK WILL BE USED ON 2-PLEX UNIT, THE VARIOUS COMBINATIONS WILL FALL UNDER LOCAL JURISDICTION.
C6: DESIGN SUMMATION
C8: PROJECT NAME: | D8: =Specs!I9 -> MODULAR OFFICE COMPLEX | M8: TYPE | N8: SF | O8: OCCUPANTS | P8: HVAC | Q8: KW HEAT | R8: VENTILATION OCCUPANCY | S8: OUTSIDE CFM REQUIRED
M9: 2 PLEX | N9: =825*2 -> 1650 | O9: 16 | P9: 6 TONS | Q9: 20 | R9: =ROUND(N9*0.007,0) -> 12 | S9: =R9*20 -> 240
C10: Building width: | D10: =Inputs!E7 -> 17.75 | E10: Total SF: | F10: =Inputs!E28 -> 994 | M10: 3 PLEX | N10: =825*3 -> 2475 | O10: 24 | P10: 9 TONS | Q10: 28 | R10: =ROUND(N10*0.007,0) -> 17 | S10: =R10*20 -> 340
C11: Building length: | D11: =Inputs!E8 -> 56 | M11: 4 PLEX | N11: =825*4 -> 3300 | O11: 33 | P11: 12 TONS | Q11: 36 | R11: =ROUND(N11*0.007,0) -> 23 | S11: =R11*20 -> 460 | U11: =10+8+8+10 -> 36
C12: Number units: | D12: =Inputs!T10 -> 1 | F12: Ventilation Occupancy: | H12: ='AC duct'!C17 -> 7 | M12: 5 PLEX | N12: =825*5 -> 4125 | O12: 41 | P12: 15 TONS | Q12: 41 | R12: =ROUND(N12*0.007,0) -> 29 | S12: =R12*20 -> 580 | U12: =10+8+5+8+10 -> 41
C13: Occupancy Group: | D13: =Inputs!E24 -> B | F13: Ventilation CFM Reqd: | H13: ='AC duct'!C19 -> 140 | M13: 6 PLEX | N13: =825*6 -> 4950 | O13: 49 | P13: 18 TONS | Q13: 49 | R13: =ROUND(N13*0.007,0) -> 35 | S13: =R13*20 -> 700 | U13: =10+8+8+5+8+10 -> 49
C14: IBC Occupants: | D14: =Specs!I20 -> 0 | M14: 7 PLEX | N14: =825*7 -> 5775 | O14: 57 | P14: 21 TONS | Q14: 57 | R14: =ROUND(N14*0.007,0) -> 40 | S14: =R14*20 -> 800 | U14: =10+8+8+5+8+8+10 -> 57
M15: 8 PLEX | N15: =825*8 -> 6600 | O15: 66 | P15: 24 TONS | Q15: 65 | R15: =ROUND(N15*0.007,0) -> 46 | S15: =R15*20 -> 920 | U15: =10+8+8+5+8+8+8+10 -> 65
C16: Approx. Unit Weight: | D16: =Inputs!E11 -> 27832
C17: Approx. Building Weight: | D17: =Inputs!T11 -> 27832
C18: Axles needed PER UNIT: | D18: =Inputs!T12/Inputs!T10 -> 6
C20: Codes: | F20: Design Loads:
C21: =Specs!G12 -> ELECTRICAL: NEC-2008 | F21: Roof: | G21: =Specs!J24 -> 30
C22: =Specs!G13 -> BUILDING: IBC-2006 | F22: Floor: | G22: =Specs!J25 -> 50
C23: =Specs!G14 -> PLUMBING: IPC-2006 | F23: Conc. Floor | G23: =Specs!J26 -> 2000 LBS
C24: =Specs!G15 -> MECHANICAL: IMC-2006 | F24: Wind: | G24: =Specs!J27 -> (130 MPH 3-SEC GUST)
C25: =Specs!G16 -> ENERGY: IEEC-2006 | F25: Exposure: | G25: =Specs!I28 -> B
F26: Sesmic: | G26: =Specs!J29 -> B
C28: Light Allowance: | D28: =IF(Inputs!E24=Inputs!E31,Inputs!J40,Inputs!J45) -> 14.617647 | E28: 3-Bulb Fixtures
C29: Water Closets: | D29: =IF(Inputs!E24=Inputs!E31,Inputs!E59,Inputs!E60) -> 1
C30: Lavitories: | D30: =IF(Inputs!E24=Inputs!E31,Inputs!F59,Inputs!F60) -> 1
C31: Water Fountains: | D31: =IF(Inputs!E24=Inputs!E31,Inputs!G59,Inputs!G60) -> 1
C32: Service Sinks: | D32: 1
C33: Urinals
C35: Skirting 4'x12' sheets: | D35: =Inputs!G36 -> 10
C36: Skirting vents req'd: | D36: =Inputs!F37 -> 7

Sheet Sheet1
